Workbook

Sheet Master Plan
A1: Master Order | B1: Phase / Timing | C1: Lane | D1: Resource / Activity | E1: Provider | F1: Priority | G1: Effort (h) | H1: What to Do | I1: Proof / Deliverable | J1: Source Sheet | K1: Detail | L1: External Link | M1: Status | N1: Notes | O1: Target Start | P1: Target Finish | R1: =HYPERLINK("#'Competency Matrix'!A1","Open Competency Matrix") -> Open Competency Matrix
A2: 1 | B2: Week 1 — Agent fundamentals | C2: CORE — Agent Engineering | D2: Build Agents with Agent Development Kit (ADK) | E2: Google Skills / GEAR | F2: VERY HIGH | G2: 0.5 | H2: Understand ADK's code-first agent model and core abstractions. | I2: Sketch an agent loop and map ADK Agent/Tool/Session concepts onto it. | J2: Roadmap | K2: Go to detail | L2: Open resource | M2: Done | N2: 1-page architecture note: 'What ADK abstracts vs what it does not'. | O2: 46296 | P2: 46302 | R2: =HYPERLINK("#'Revision'!A1","Revision / Refresh Guide") -> Revision / Refresh Guide
A3: 2 | B3: Week 1 — First ADK agent | C3: CORE — Agent Engineering | D3: Build Your First Agent with ADK | E3: Google Skills / GEAR | F3: VERY HIGH | G3: 1 | H3: Create, configure, and run ADK agents in Python/YAML. | I3: Build the lab, close instructions, then recreate from memory with one custom behavior. | J3: Roadmap | K3: Go to detail | L3: Open resource | M3: Not Started | N3: Repo: first-adk-agent + README + run instructions. | O3: 46296 | P3: 46302
A4: 3 | B4: Week 1 — ADK foundations | C4: CORE — Agent Engineering | D4: Building AI Agents with ADK: The Foundation | E4: Google Codelabs | F4: VERY HIGH | G4: 1 | H4: Set up ADK and build a foundational conversational agent. | I4: Complete codelab, then add structured output and one failure test. | J4: Roadmap | K4: Go to detail | L4: Open resource | M4: Not Started | N4: Commit tagged foundation-v1 with tests. | O4: 46296 | P4: 46302
A5: 4 | B5: Week 1 — ADK mental model | C5: CORE — Agent Engineering | D5: Introducing Agent Development Kit | E5: YouTube — Google for Developers | F5: HIGH | G5: 0.3 | H5: Understand ADK design goals: model/deployment agnosticism, multi-agent, debugging. | I5: Take notes only on architectural primitives; compare with your own agent loop. | J5: Roadmap | K5: Go to detail | L5: Open resource | M5: Not Started | N5: Architecture comparison notes. | O5: 46296 | P5: 46302
A6: 5 | B6: From Week 1 — 3–5 problems/week in parallel | C6: PARALLEL — CS / Interview | D6: LeetCode 75 | E6: LeetCode | F6: VERY HIGH | H6: Complete if rusty; otherwise use as diagnostic and focus on weak patterns. | I6: Solve without hints; after each problem record pattern, complexity, edge cases, and one alternate solution. | J6: CS + Interview Track | K6: Go to detail | L6: Open resource | M6: Not Started | N6: Google-style engineering interviews still require fast, correct algorithmic reasoning. | O6: 46296 | P6: 46379
A7: 6 | B7: From Week 1 — Parallel refresh | C7: PARALLEL — CS / Interview | D7: MIT 6.006 — Introduction to Algorithms | E7: MIT OpenCourseWare | F7: HIGH | H7: Selective refresh: hashing, graphs, shortest paths, dynamic programming, complexity; do problem sets for weak areas. | I7: Complete 2–3 MIT problem sets from your weakest topics without solutions, then compare. | J7: CS + Interview Track | K7: Go to detail | L7: Open resource | M7: Not Started | N7: Deepens the reasoning behind interview patterns rather than memorizing LeetCode templates. | O7: 46296 | P7: 46351
A8: 7 | B8: From Week 1 — Selective | C8: PARALLEL — CS / Interview | D8: MIT 6.034 — Artificial Intelligence | E8: MIT OpenCourseWare | F8: MEDIUM | H8: Select search, planning, constraints and probabilistic reasoning; skip material duplicated by stronger modern sources. | I8: Implement A*/minimax or a constraint solver and explicitly compare its deterministic search with LLM planning. | J8: CS + Interview Track | K8: Go to detail | L8: Open resource | M8: Not Started | N8: Gives historical/algorithmic grounding for planning and search techniques that reappear in modern agents. | O8: 46296 | P8: 46337
A9: 8 | B9: From Week 1 — Selective / project-driven | C9: PARALLEL — CS / Interview | D9: CS50's Introduction to Artificial Intelligence with Python | E9: Harvard / edX | F9: HIGH | H9: Selective completion recommended for an experienced engineer: search, uncertainty, optimization, learning and language projects. | I9: Complete at least 3 projects from topics where your intuition is weakest; explain algorithmic choices and failure cases. | J9: CS + Interview Track | K9: Go to detail | L9: Open resource | M9: Not Started | N9: Hands-on classical AI and ML fundamentals with real Python projects; good gap detector before deeper research material. | O9: 46296 | P9: 46351
A10: 9 | B10: Week 2 — ADK deep foundation | C10: CORE — Agent Engineering | D10: ADK Training Modules 1–7 | E10: Maurizio Ipsale | F10: VERY HIGH | G10: 4 | H10: Environment, LlmAgent, programmatic runs, model portability, multimodal. | I10: Run every module; rebuild modules 3, 4.5 and 6 without copying. | J10: Roadmap | K10: Go to detail | L10: Open resource | M10: Not Started | N10: Annotated repo fork/branch + lessons.md. | O10: 46303 | P10: 46309
A11: 10 | B11: Week 2 — Tools | C11: CORE — Agent Engineering | D11: Building AI Agents with ADK: Empowering with Tools | E11: Google Codelabs | F11: VERY HIGH | G11: 1.5 | H11: Function tools, built-in search, third-party tools, sub-agents. | I11: Add 3 tools to one agent; write schema/argument edge-case tests. | J11: Roadmap | K11: Go to detail | L11: Open resource | M11: Not Started | N11: Tool contract tests + failure matrix. | O11: 46303 | P11: 46309
A12: 11 | B12: Week 3 — Tools & grounding | C12: CORE — Agent Engineering | D12: ADK Training Modules 8–14 | E12: Maurizio Ipsale | F12: VERY HIGH | G12: 5 | H12: Custom tools, ToolContext, OpenAPI, grounding, HITL, persistence, third-party tools. | I12: Build an agent with stateful tool calls, OpenAPI integration, and an approval gate. | J12: Roadmap | K12: Go to detail | L12: Open resource | M12: Not Started | N12: Repo: tool-rich-agent + test suite. | O12: 46310 | P12: 46316
A13: 12 | B13: Week 3 — Tool engineering | C13: CORE — Agent Engineering | D13: Writing effective tools for agents — with agents | E13: Anthropic Engineering | F13: VERY HIGH | G13: 1 | H13: Design tool interfaces that agents can select and use reliably. | I13: Take one existing tool API; redesign name, description, schema, and output for agent use. A/B eval it. | J13: Roadmap | K13: Go to detail | L13: Open resource | M13: Not Started | N13: Before/after tool eval report. | O13: 46310 | P13: 46316
A14: 13 | B14: Week 3 — Agent patterns | C14: CORE — Agent Engineering | D14: Building more effective AI agents | E14: YouTube — Anthropic | F14: VERY HIGH | G14: 0.4 | H14: Learn simple agent patterns, subagents, skills, MCP and common failure modes. | I14: Implement one pattern without a framework: routing or parallel subagents. | J14: Roadmap | K14: Go to detail | L14: Open resource | M14: Not Started | N14: Small pure-Python pattern repo. | O14: 46310 | P14: 46316
A15: 14 | B15: Weeks 3–5 | C15: PARALLEL — Data / RAG / Graph | D15: Vector Search and Embeddings | E15: Google Skills / GEAR | F15: VERY HIGH | H15: Learn embeddings, semantic search, hybrid retrieval and grounded RAG before adding agent orchestration. | I15: Build a small corpus; compare keyword, vector and hybrid retrieval on a labeled query set. | J15: Data + RAG Track | K15: Go to detail | L15: Open resource | M15: Not Started | N15: Retrieval benchmark with Recall@K / MRR + failure notes | O15: 46310 | P15: 46330
A16: 15 | B16: From Week 3 — 2–3 h/week | C16: PARALLEL — CS / Interview | D16: Grokking Modern System Design Interview | E16: Educative | F16: VERY HIGH | H16: Prioritize distributed-system fundamentals + 8–10 case studies + mock interviews. | I16: Do one 45-minute design from a blank page weekly; record requirements, estimates, API/data model, failure modes and tradeoffs. | J16: CS + Interview Track | K16: Go to detail | L16: Open resource | M16: Not Started | N16: Senior Google/Anthropic roles require architecture tradeoffs, reliability, consistency, capacity, queues, caches and failure handling. | O16: 46310 | P16: 46393
A17: 16 | B17: Week 4 — MCP fundamentals | C17: CORE — Agent Engineering | D17: Model Context Protocol (MCP): Hands-On with Agentic AI | E17: LinkedIn Learning | F17: HIGH | G17: 0.9 | H17: Use MCP clients/servers and build Python/TypeScript MCP servers. | I17: Build a small MCP server, inspect it, then connect it from Claude and one other client. | J17: Roadmap | K17: Go to detail | L17: Open resource | M17: Not Started | N17: Repo: mcp-server-lab. | O17: 46317 | P17: 46323
A18: 17 | B18: Week 4 — MCP in ADK | C18: CORE — Agent Engineering | D18: ADK Training Modules 27–28 | E18: Maurizio Ipsale | F18: VERY HIGH | G18: 1.5 | H18: Build and consume MCP tools with ADK. | I18: Expose one internal service through MCP; add auth/error handling. | J18: Roadmap | K18: Go to detail | L18: Open resource | M18: Not Started | N18: Production-style MCP service skeleton. | O18: 46317 | P18: 46323
A19: 18 | B19: Week 4 — MCP + ADK + A2A | C19: CORE — Agent Engineering | D19: Getting Started with MCP, ADK and A2A | E19: Google Codelabs | F19: VERY HIGH | G19: 2 | H19: Build MCP server, deploy to Cloud Run, use with ADK, expose agent via A2A. | I19: Complete lab, then replace currency tool with your own business domain. | J19: Roadmap | K19: Go to detail | L19: Open resource | M19: Not Started | N19: Cross-protocol architecture diagram + runnable repo. | O19: 46317 | P19: 46323
A20: 19 | B20: Weeks 4–6 | C20: PARALLEL — Data / RAG / Graph | D20: Building Agents with Retrieval-Augmented Generation | E20: Google Codelabs | F20: VERY HIGH | H20: Connect retrieval and structured tools to an ADK agent so the model decides when and how to retrieve. | I20: Complete the financial-analysis lab, then replace one data source with your own corpus/API. | J20: Data + RAG Track | K20: Go to detail | L20: Open resource | M20: Not Started | N20: Agentic-RAG repo + eval set | O20: 46317 | P20: 46337
A21: 20 | B21: Week 5 — MCP efficiency | C21: CORE — Agent Engineering | D21: Code execution with MCP: Building more efficient agents | E21: Anthropic Engineering | F21: VERY HIGH | G21: 0.8 | H21: Understand context cost of tool definitions/results and code-mediated tool use. | I21: Benchmark direct tool calls vs code execution across 20 tasks: tokens, latency, success. | J21: Roadmap | K21: Go to detail | L21: Open resource | M21: Not Started | N21: Benchmark notebook/report. | O21: 46324 | P21: 46330
A22: 21 | B22: Week 5 — MCP deeper dive | C22: CORE — Agent Engineering | D22: Introduction to Model Context Protocol by Anthropic | E22: LinkedIn Learning | F22: HIGH | G22: 1 | H22: Build MCP servers/clients with tools, resources and prompts. | I22: Implement document-management MCP project; add one resource and one prompt primitive. | J22: Roadmap | K22: Go to detail | L22: Open resource | M22: Not Started | N22: MCP primitives reference implementation. | O22: 46324 | P22: 46330
A23: 22 | B23: Week 5 — Multi-agent fundamentals | C23: CORE — Agent Engineering | D23: ADK Training Modules 15–21.5 | E23: Maurizio Ipsale | F23: VERY HIGH | G23: 4.5 | H23: Static/dynamic orchestration, routing, collaboration, cycles, distributed graphs. | I23: Recreate 3 orchestration patterns from memory and compare failure modes. | J23: Roadmap | K23: Go to detail | L23: Open resource | M23: Not Started | N23: Patterns repo + decision matrix. | O23: 46324 | P23: 46330
A24: 23 | B24: Weeks 5–7 | C24: PARALLEL — Data / RAG / Graph | D24: Vertex AI RAG Engine quickstart | E24: Google Cloud | F24: HIGH | H24: Understand production corpus ingestion, managed retrieval, metadata and retrieval APIs. | I24: Create a RAG corpus, ingest documents, retrieve contexts, and instrument latency/cost. | J24: Data + RAG Track | K24: Go to detail | L24: Open resource | M24: Not Started | N24: RAG Engine notebook + architecture note | O24: 46324 | P24: 46344
A25: 24 | B25: Weeks 5–7 | C25: PARALLEL — Data / RAG / Graph | D25: Reranking for Vertex AI RAG Engine | E25: Google Cloud | F25: VERY HIGH | H25: Retrieval quality often dominates answer quality; reranking is a core production technique. | I25: Compare baseline top-K retrieval vs reranked retrieval on at least 30 labeled queries. | J25: Data + RAG Track | K25: Go to detail | L25: Open resource | M25: Not Started | N25: Before/after retrieval metrics + cost/latency | O25: 46324 | P25: 46344
A26: 25 | B26: From Week 5 — 1 topic/week | C26: PARALLEL — CS / Interview | D26: MIT 6.824 — Distributed Computer Systems Engineering | E26: MIT OpenCourseWare | F26: VERY HIGH | H26: Selective deep study: fault tolerance, replication, consistency, distributed storage, naming and failure recovery. | I26: Write design notes applying replication/consistency/failure concepts to an agent runtime, tool service and memory service. | J26: CS + Interview Track | K26: Go to detail | L26: Open resource | M26: Not Started | N26: Agent platforms are distributed systems with stochastic components; these concepts remain foundational even though this OCW edition is older. | O26: 46324 | P26: 46393
A27: 26 | B27: Week 6 — Distributed multi-agent | C27: CORE — Agent Engineering | D27: Architect Multi-Agent Systems with ADK | E27: Google Skills / GEAR | F27: VERY HIGH | G27: 3 | H27: Collaborative workflows, shared state, distributed communication and deployment. | I27: Build a supervisor + 3 specialists with explicit shared-state rules. | J27: Roadmap | K27: Go to detail | L27: Open resource | M27: Not Started | N27: System diagram + orchestration tests. | O27: 46331 | P27: 46337
A28: 27 | B28: Week 6 — A2A | C28: CORE — Agent Engineering | D28: Multi-Agent Systems with Agent2Agent | E28: Google Codelabs | F28: VERY HIGH | G28: 0.75 | H28: Agent Cards, A2A servers, remote connections and host orchestration. | I28: Complete lab; add versioned Agent Card and simulated remote failure. | J28: Roadmap | K28: Go to detail | L28: Open resource | M28: Not Started | N28: A2A contract test suite. | O28: 46331 | P28: 46337
A29: 28 | B29: Week 6 — MCP + A2A cross-vendor | C29: CORE — Agent Engineering | D29: Hands-On AI: MCP and Agent2Agent (A2A) | E29: LinkedIn Learning | F29: HIGH | G29: 1.7 | H29: MCP server/client and multi-agent A2A design/implementation. | I29: Implement HR-style example using a different domain and at least 2 independent processes. | J29: Roadmap | K29: Go to detail | L29: Open resource | M29: Not Started | N29: Interoperability demo. | O29: 46331 | P29: 46337
A30: 29 | B30: Weeks 6–9 | C30: PARALLEL — Data / RAG / Graph | D30: Build a RAG evaluation harness | E30: Self-directed | F30: VERY HIGH | H30: A RAG system needs separate retrieval and generation metrics; end-answer quality alone hides failure causes. | I30: Measure Recall@K/MRR/nDCG, context precision, groundedness, answer relevance and citation correctness. | J30: Data + RAG Track | K30: Go to detail | L30: Open resource | M30: Not Started | N30: Reusable rag-evals package | O30: 46331 | P30: 46358
A31: 30 | B31: Week 7 — Production multi-agent | C31: CORE — Agent Engineering | D31: Build a Multi-Agent Creative Studio with ADK, A2A, MCP | E31: Google Codelabs | F31: VERY HIGH | G31: 3 | H31: Distributed agents on Cloud Run, Agent Runtime, MCP, Skills, quality-control loop, context compaction. | I31: Complete lab; replace creative domain with architecture-review workflow. | J31: Roadmap | K31: Go to detail | L31: Open resource | M31: Not Started | N31: Deployed multi-agent portfolio project v1. | O31: 46338 | P31: 46344
A32: 31 | B32: Week 7 — Multi-agent production lessons | C32: CORE — Agent Engineering | D32: How we built our multi-agent research system | E32: Anthropic Engineering | F32: VERY HIGH | G32: 1 | H32: Learn orchestrator-worker architecture, parallel exploration, eval and reliability lessons. | I32: Clone the pattern for a research task and compare single-agent vs multi-agent cost/quality. | J32: Roadmap | K32: Go to detail | L32: Open resource | M32: Not Started | N32: Experiment report with metrics. | O32: 46338 | P32: 46344
A33: 32 | B33: Weeks 7–9 | C33: PARALLEL — Data / RAG / Graph | D33: Getting started with Spanner Graph | E33: Google Codelabs | F33: HIGH | H33: Learn property graphs, nodes/edges, ISO GQL pattern matching, traversal, and relational/graph interoperability. | I33: Complete the codelab, then model one domain from your capstone as nodes/edges and write 8 GQL queries. | J33: Data + RAG Track | K33: Go to detail | L33: Open resource | M33: Not Started | N33: Graph schema + GQL query pack | O33: 46338 | P33: 46358
A34: 33 | B34: Week 8 — State & memory | C34: CORE — Agent Engineering | D34: ADK Training Modules 22–23 | E34: Maurizio Ipsale | F34: VERY HIGH | G34: 1.5 | H34: State, memory and artifacts for production agents. | I34: Implement session state + cross-session memory + artifact store; document retention rules. | J34: Roadmap | K34: Go to detail | L34: Open resource | M34: Not Started | N34: State/memory design doc + tests. | O34: 46345 | P34: 46351
A35: 34 | B35: Week 8 — Context engineering | C35: CORE — Agent Engineering | D35: Effective context engineering for AI agents | E35: Anthropic Engineering | F35: VERY HIGH | G35: 1 | H35: Treat context as a finite resource; decide what enters, persists, and is retrieved. | I35: Instrument context size; implement compaction/retrieval policy and compare outcomes. | J35: Roadmap | K35: Go to detail | L35: Open resource | M35: Not Started | N35: Context-budget benchmark. | O35: 46345 | P35: 46351
A36: 35 | B36: Weeks 8–11 | C36: PARALLEL — Data / RAG / Graph | D36: GraphRAG infrastructure using Agent Platform and Spanner Graph | E36: Google Cloud Architecture Center | F36: VERY HIGH | H36: GraphRAG combines vector retrieval with graph traversal for relationship-aware, multi-hop context. | I36: Design ingestion + serving architecture; explicitly decide what belongs in vectors, relational columns and graph edges. | J36: Data + RAG Track | K36: Go to detail | L36: Open resource | M36: Not Started | N36: Architecture diagram + ADR | O36: 46345 | P36: 46372
A37: 36 | B37: From Week 8 — 1 design every 1–2 weeks | C37: PARALLEL — CS / Interview | D37: Grokking the Machine Learning System Design Interview | E37: Educative | F37: VERY HIGH | H37: Complete the framework plus LLM/semantic-search/evaluation-related cases; selectively skim familiar ML basics. | I37: Design an LLM/agent platform under explicit latency, cost, eval, safety and rollout constraints. | J37: CS + Interview Track | K37: Go to detail | L37: Open resource | M37: Not Started | N37: Bridges model quality, data, serving, experimentation and production architecture—the exact interface AI architects need. | O37: 46345 | P37: 46407
A38: 37 | B38: Week 9 — Evaluation | C38: CORE — Agent Engineering | D38: ADK Training Module 24 — Evaluation | E38: Maurizio Ipsale | F38: VERY HIGH | G38: 1 | H38: Create reproducible agent evaluations. | I38: Create 30-task golden set; measure task success, tool choice and argument correctness. | J38: Roadmap | K38: Go to detail | L38: Open resource | M38: Not Started | N38: evals/ directory in main project. | O38: 46352 | P38: 46358
A39: 38 | B39: Week 9 — Agent evals | C39: CORE — Agent Engineering | D39: AI Evaluations: Foundations and Practical Examples | E39: LinkedIn Learning | F39: VERY HIGH | G39: 2.1 | H39: Build practical AI/agent evaluation methods. | I39: Add deterministic + LLM-judge graders; manually audit a sample of judge decisions. | J39: Roadmap | K39: Go to detail | L39: Open resource | M39: Not Started | N39: Evaluator calibration report. | O39: 46352 | P39: 46358
A40: 39 | B40: Week 9 — Agent eval methodology | C40: CORE — Agent Engineering | D40: Demystifying evals for AI agents | E40: Anthropic Engineering | F40: VERY HIGH | G40: 1 | H40: Design multi-turn agent evals that grade outcomes and trajectories. | I40: Expand golden set to 100 tasks split easy/medium/hard/adversarial. | J40: Roadmap | K40: Go to detail | L40: Open resource | M40: Not Started | N40: Public benchmark README + failure taxonomy. | O40: 46352 | P40: 46358
...

Sheet Dashboard
A1: Agentic AI Mastery — Study & Portfolio Tracker
A3: Goal: Google / Anthropic-level agent engineering depth — courses are inputs; code, evals, production and technical reasoning are the outputs. | B3: Goal: Google / Anthropic-level agent engineering depth — courses are inputs; code, evals, production and technical reasoning are the outputs. | C3: Goal: Google / Anthropic-level agent engineering depth — courses are inputs; code, evals, production and technical reasoning are the outputs. | D3: Goal: Google / Anthropic-level agent engineering depth — courses are inputs; code, evals, production and technical reasoning are the outputs. | E3: Goal: Google / Anthropic-level agent engineering depth — courses are inputs; code, evals, production and technical reasoning are the outputs. | F3: Goal: Google / Anthropic-level agent engineering depth — courses are inputs; code, evals, production and technical reasoning are the outputs. | G3: Goal: Google / Anthropic-level agent engineering depth — courses are inputs; code, evals, production and technical reasoning are the outputs. | H3: Goal: Google / Anthropic-level agent engineering depth — courses are inputs; code, evals, production and technical reasoning are the outputs.
A5: KPI | B5: Value | D5: Hands-On KPI | E5: Value | G5: Readiness KPI | H5: Value
A6: Roadmap items | B6: =COUNTA(Roadmap!E2:E100) -> 53 | D6: Labs | E6: =COUNTA('Hands-On Labs'!B2:B50) -> 18 | G6: Overall competency readiness | H6: =AVERAGE('Competency Matrix'!E2:E26) -> 0
A7: Completed | B7: =COUNTIF(Roadmap!M2:M100,"Done") -> 1 | D7: Labs completed | E7: =COUNTIF('Hands-On Labs'!I2:I50,"Done") -> 0 | G7: Competencies at target | H7: =COUNTIF('Competency Matrix'!O2:O26,0) -> 0
A8: VERY HIGH priority items | B8: =COUNTIF(Roadmap!H2:H100,"VERY HIGH") -> 39 | D8: Capstone labs | E8: =COUNTIF('Hands-On Labs'!C2:C50,"Capstone") -> 1 | G8: Program end | H8: 46435
A9: Planned learning hours | B9: =SUM(Roadmap!I2:I100) -> 205.65 | D9: Planned lab hours | E9: =SUM('Hands-On Labs'!H2:H50) -> 147
D10: Link audit | E10: Platform Library re-audited Sep 5, 2026: 62/62 destinations validated; no confirmed broken links. All rows now have an explicit native clickable Open Link plus a copyable URL and audit note. | G10: =HYPERLINK("#'Revision'!A1","Revision / Refresh Guide") -> Revision / Refresh Guide
A12: Provider | B12: Roadmap Items | D12: Status | E12: Count
A13: Google Skills / GEAR | B13: =COUNTIF(Roadmap!F2:F100,A13) -> 5 | D13: Not Started | E13: =COUNTIF(Roadmap!M2:M100,D13) -> 52
A14: Google Codelabs | B14: =COUNTIF(Roadmap!F2:F100,A14) -> 7 | D14: In Progress | E14: =COUNTIF(Roadmap!M2:M100,D14) -> 0
A15: Maurizio Ipsale | B15: =COUNTIF(Roadmap!F2:F100,A15) -> 9 | D15: Done | E15: =COUNTIF(Roadmap!M2:M100,D15) -> 1
A16: Anthropic Engineering | B16: =COUNTIF(Roadmap!F2:F100,A16) -> 9 | D16: Skipped | E16: =COUNTIF(Roadmap!M2:M100,D16) -> 0
A17: LinkedIn Learning | B17: =COUNTIF(Roadmap!F2:F100,A17) -> 7
A18: Udemy | B18: =COUNTIF(Roadmap!F2:F100,A18) -> 2
A19: YouTube — Anthropic | B19: =COUNTIF(Roadmap!F2:F100,A19) -> 2 | D19: Operating Rule | E19: What it means
A20: YouTube — Google for Developers | B20: =COUNTIF(Roadmap!F2:F100,A20) -> 3 | D20: 30 / 70 | E20: ~30% courses/reading; ~70% building, breaking, measuring, deploying.
A21: Kaggle + Google | B21: =COUNTIF(Roadmap!F2:F100,A21) -> 2 | D21: Rebuild from memory | E21: After guided labs, close the instructions and reproduce the core design.
A22: Google ADK Docs | B22: =COUNTIF(Roadmap!F2:F100,A22) -> 1 | D22: Evals before claims | E22: Never call an agent 'good' without a repeatable task set and metrics.
A23: Self-directed | B23: =COUNTIF(Roadmap!F2:F100,A23) -> 5 | D23: Protocol > framework | E23: Be able to explain and implement MCP/A2A concepts outside ADK.
D24: Portfolio > badge count | E24: Four excellent repos with measured tradeoffs beat dozens of tutorial repos.
A25: Stanford | B25: =COUNTIF(Roadmap!F2:F100,A25) -> 1 | D25: Parallel interview track | E25: Run CS + Interview Track at ~3–5 h/week alongside the 20-week agent roadmap; do not replace build/eval/deployment time with interview grinding.
D26: Master navigation | E26: Use Master Plan as the canonical sequence; every item links to its detail sheet and external source.
D27: Program dates | E27: Oct 1, 2026 → Feb 17, 2027 (20 seven-day study blocks).
D28: Competency matrix | E28: Use Current Level 0–4 to turn course completion into measurable readiness and evidence gaps.

Sheet Roadmap
A1: Stage | B1: Order | C1: Week | D1: Topic | E1: Resource | F1: Provider | G1: Type | H1: Priority | I1: Est. Hours | J1: Target Outcome | K1: Hands-on Proof | L1: Portfolio Evidence | M1: Status | N1: Back to Master Plan
A2: 1 | B2: 1 | C2: 1 | D2: Agent fundamentals | E2: Build Agents with Agent Development Kit (ADK) | F2: Google Skills / GEAR | G2: Course | H2: VERY HIGH | I2: 0.5 | J2: Understand ADK's code-first agent model and core abstractions. | K2: Sketch an agent loop and map ADK Agent/Tool/Session concepts onto it. | L2: 1-page architecture note: 'What ADK abstracts vs what it does not'. | M2: Done | N2: https://www.skills.google/course_templates/1585
A3: 1 | B3: 2 | C3: 1 | D3: First ADK agent | E3: Build Your First Agent with ADK | F3: Google Skills / GEAR | G3: Hands-on course | H3: VERY HIGH | I3: 1 | J3: Create, configure, and run ADK agents in Python/YAML. | K3: Build the lab, close instructions, then recreate from memory with one custom behavior. | L3: Repo: first-adk-agent + README + run instructions. | M3: Not Started | N3: https://partner.skills.google/course_templates/1563
A4: 1 | B4: 3 | C4: 1 | D4: ADK foundations | E4: Building AI Agents with ADK: The Foundation | F4: Google Codelabs | G4: Codelab | H4: VERY HIGH | I4: 1 | J4: Set up ADK and build a foundational conversational agent. | K4: Complete codelab, then add structured output and one failure test. | L4: Commit tagged foundation-v1 with tests. | M4: Not Started | N4: https://codelabs.developers.google.com/devsite/codelabs/build-agents-with-adk-foundation
A5: 1 | B5: 4 | C5: 1 | D5: ADK mental model | E5: Introducing Agent Development Kit | F5: YouTube — Google for Developers | G5: Video | H5: HIGH | I5: 0.3 | J5: Understand ADK design goals: model/deployment agnosticism, multi-agent, debugging. | K5: Take notes only on architectural primitives; compare with your own agent loop. | L5: Architecture comparison notes. | M5: Not Started | N5: https://www.youtube.com/watch?v=zgrOwow_uTQ
A6: 1 | B6: 5 | C6: 2 | D6: ADK deep foundation | E6: ADK Training Modules 1–7 | F6: Maurizio Ipsale | G6: Hands-on modules | H6: VERY HIGH | I6: 4 | J6: Environment, LlmAgent, programmatic runs, model portability, multimodal. | K6: Run every module; rebuild modules 3, 4.5 and 6 without copying. | L6: Annotated repo fork/branch + lessons.md. | M6: Not Started | N6: https://mauripsale.github.io/doc-adk-training/docs/
A7: 2 | B7: 6 | C7: 2 | D7: Tools | E7: Building AI Agents with ADK: Empowering with Tools | F7: Google Codelabs | G7: Codelab | H7: VERY HIGH | I7: 1.5 | J7: Function tools, built-in search, third-party tools, sub-agents. | K7: Add 3 tools to one agent; write schema/argument edge-case tests. | L7: Tool contract tests + failure matrix. | M7: Not Started | N7: https://codelabs.developers.google.com/devsite/codelabs/build-agents-with-adk-empowering-with-tools
A8: 2 | B8: 7 | C8: 3 | D8: Tools & grounding | E8: ADK Training Modules 8–14 | F8: Maurizio Ipsale | G8: Hands-on modules | H8: VERY HIGH | I8: 5 | J8: Custom tools, ToolContext, OpenAPI, grounding, HITL, persistence, third-party tools. | K8: Build an agent with stateful tool calls, OpenAPI integration, and an approval gate. | L8: Repo: tool-rich-agent + test suite. | M8: Not Started | N8: https://github.com/mauripsale/doc-adk-training
A9: 2 | B9: 8 | C9: 3 | D9: Tool engineering | E9: Writing effective tools for agents — with agents | F9: Anthropic Engineering | G9: Article | H9: VERY HIGH | I9: 1 | J9: Design tool interfaces that agents can select and use reliably. | K9: Take one existing tool API; redesign name, description, schema, and output for agent use. A/B eval it. | L9: Before/after tool eval report. | M9: Not Started | N9: https://www.anthropic.com/engineering/writing-tools-for-agents
A10: 2 | B10: 9 | C10: 3 | D10: Agent patterns | E10: Building more effective AI agents | F10: YouTube — Anthropic | G10: Video | H10: VERY HIGH | I10: 0.4 | J10: Learn simple agent patterns, subagents, skills, MCP and common failure modes. | K10: Implement one pattern without a framework: routing or parallel subagents. | L10: Small pure-Python pattern repo. | M10: Not Started | N10: https://www.youtube.com/watch?v=uhJJgc-0iTQ
A11: 3 | B11: 10 | C11: 4 | D11: MCP fundamentals | E11: Model Context Protocol (MCP): Hands-On with Agentic AI | F11: LinkedIn Learning | G11: Course | H11: HIGH | I11: 0.9 | J11: Use MCP clients/servers and build Python/TypeScript MCP servers. | K11: Build a small MCP server, inspect it, then connect it from Claude and one other client. | L11: Repo: mcp-server-lab. | M11: Not Started | N11: https://www.linkedin.com/learning/model-context-protocol-mcp-hands-on-with-agentic-ai
A12: 3 | B12: 11 | C12: 4 | D12: MCP in ADK | E12: ADK Training Modules 27–28 | F12: Maurizio Ipsale | G12: Hands-on modules | H12: VERY HIGH | I12: 1.5 | J12: Build and consume MCP tools with ADK. | K12: Expose one internal service through MCP; add auth/error handling. | L12: Production-style MCP service skeleton. | M12: Not Started | N12: https://mauripsale.github.io/doc-adk-training/docs/
A13: 3 | B13: 12 | C13: 4 | D13: MCP + ADK + A2A | E13: Getting Started with MCP, ADK and A2A | F13: Google Codelabs | G13: Codelab | H13: VERY HIGH | I13: 2 | J13: Build MCP server, deploy to Cloud Run, use with ADK, expose agent via A2A. | K13: Complete lab, then replace currency tool with your own business domain. | L13: Cross-protocol architecture diagram + runnable repo. | M13: Not Started | N13: https://codelabs.developers.google.com/codelabs/currency-agent
... A49: 11 | B49: 48 | C49: 17 | D49: Protocols overview | E49: How to build an AI agent with MCP, ADK, and A2A on Google Cloud | F49: YouTube — Google for Developers | G49: Video | H49: HIGH | I49: 0.25 | J49: End-to-end visual walkthrough of MCP + ADK + A2A architecture. | K49: Redraw architecture from memory and annotate trust boundaries. | L49: Annotated architecture diagram. | M49: Not Started | N49: https://www.youtube.com/watch?v=6mQwHqK1I5w
A50: 12 | B50: 49 | C50: 18 | D50: Framework-free mastery | E50: Build a minimal agent runtime from scratch | F50: Self-directed | G50: Capstone lab | H50: VERY HIGH | I50: 12 | J50: Internalize agent loop, tools, state, planner/router, retries, tracing and eval hooks. | K50: Implement 2k–4k LOC Python runtime with tests; no LangChain/ADK/CrewAI runtime. | L50: Repo: agent-runtime-from-scratch. | M50: Not Started
A51: 12 | B51: 50 | C51: 19 | D51: Interoperability | E51: Agent protocol lab | F51: Self-directed | G51: Capstone lab | H51: VERY HIGH | I51: 8 | J51: Prove MCP/A2A and vendor interoperability. | K51: ADK coordinator + Claude-backed worker + pure Python worker; MCP tools; A2A communication. | L51: Repo: agent-protocol-lab. | M51: Not Started
A52: 12 | B52: 51 | C52: 19 | D52: Benchmarking | E52: Agent eval benchmark | F52: Self-directed | G52: Capstone lab | H52: VERY HIGH | I52: 8 | J52: Compare agent architectures using measurable quality/cost/latency/reliability. | K52: Run 100-task benchmark across single/multi-agent and at least 2 model stacks. | L52: Repo: agent-evals + results dashboard. | M52: Not Started
A53: 12 | B53: 52 | C53: 20 | D53: Production capstone | E53: Production multi-agent architecture system | F53: Self-directed | G53: Portfolio capstone | H53: VERY HIGH | I53: 16 | J53: Integrate architecture, protocols, evals, security, ops and deployment. | K53: Deploy a real multi-agent system with auth, persistence, evals, traces, HITL and CI/CD. | L53: Flagship public/private portfolio repo + architecture paper. | M53: Not Started
A54: 12 | B54: 53 | C54: 20 | D54: Technical communication | E54: Publish technical write-up | F54: Self-directed | G54: Writing | H54: VERY HIGH | I54: 4 | J54: Demonstrate senior-level reasoning, tradeoffs and clarity. | K54: Write: 'MCP vs A2A vs Agent Skills in production' using your measured examples. | L54: Public article / internal whitepaper. | M54: Not Started

Sheet Hands-On Labs
A1: # | B1: Lab | C1: Focus | D1: Activity | E1: Acceptance Criteria | F1: Evidence / Repo | G1: Target Week | H1: Est. Hours | I1: Status | K1: Back to Master Plan
A2: 1 | B2: First ADK Agent | C2: Foundations | D2: Build from memory after GEAR/codelab; add structured output + custom tool. | E2: Runs locally; README; tests 3 happy/3 failure cases; no tutorial copy-paste. | F2: first-adk-agent | G2: 1 | H2: 3 | I2: Not Started
A3: 2 | B3: Tool Contract Lab | C3: Tools | D3: Create 5 tools with typed schemas; deliberately create bad descriptions, then improve them. | E3: Measure tool-selection and argument accuracy before/after across 20 prompts. | F3: tool-contract-evals | G3: 3 | H3: 4 | I3: Not Started
A4: 3 | B4: MCP Server | C4: MCP | D4: Expose a real internal-style service via MCP with tools/resources/prompts. | E4: MCP inspector passes; auth/error paths tested; works with 2 clients. | F4: mcp-server-lab | G4: 4 | H4: 6 | I4: Not Started
A5: 4 | B5: MCP Efficiency Benchmark | C5: MCP / Context | D5: Compare direct tool calls vs code execution/dynamic tool discovery. | E5: Report success, tokens, latency, and context size on >=20 tasks. | F5: mcp-efficiency-benchmark | G5: 5 | H5: 5 | I5: Not Started
A6: 5 | B6: A2A Interop Lab | C6: A2A | D6: Build two agents as independent services with Agent Cards and A2A. | E6: Remote call works; version mismatch + timeout cases tested. | F6: a2a-interop-lab | G6: 6 | H6: 6 | I6: Not Started
A7: 6 | B7: Multi-Agent Pattern Pack | C7: Multi-agent | D7: Implement supervisor, router, parallel workers, critique/revision. | E7: Each pattern has tests + decision criteria + known failure modes. | F7: multi-agent-patterns | G7: 6 | H7: 8 | I7: Not Started
A8: 7 | B8: Cross-Vendor Agent Team | C8: Interop | D8: ADK coordinator + Claude-backed agent + pure-Python agent; MCP tools. | E8: Agents collaborate over explicit protocol boundary; vendor swap documented. | F8: cross-vendor-agent-team | G8: 7 | H8: 10 | I8: Not Started
A9: 8 | B9: Memory & Context Lab | C9: Memory | D9: Session state, persistent memory, artifacts, context compaction. | E9: Retention rules documented; context size instrumented; recovery tested. | F9: agent-memory-context | G9: 8 | H9: 6 | I9: Not Started
A10: 9 | B10: 100-Task Eval Harness | C10: Evals | D10: Build golden dataset and graders for task outcome, tool choice, args, trajectory. | E10: 100 tasks; difficulty labels; deterministic + judge graders; manual audit sample. | F10: agent-evals | G10: 9 | H10: 12 | I10: Not Started
A11: 10 | B11: Agent Observability | C11: AgentOps | D11: Instrument traces, tokens, latency, retries, tool errors, routing. | E11: Can diagnose 5 injected failures from traces alone. | F11: agent-observability | G11: 10 | H11: 6 | I11: Not Started
A12: 11 | B12: Agent Red Team | C12: Security | D12: Prompt injection, poisoned tool output, exfiltration, privilege escalation, cost loop. | E12: Threat model + mitigations; repeat attacks after fixes. | F12: agent-red-team | G12: 11 | H12: 8 | I12: Not Started
A13: 12 | B13: Cloud Run / GKE Deployment | C13: Production | D13: Deploy same agent stack to Cloud Run and GKE. | E13: Runbook, rollback, auth, secret handling, cost/ops comparison. | F13: agent-deployment-lab | G13: 12 | H13: 10 | I13: Not Started
... A17: 16 | B17: Technical Article | C17: Communication | D17: Write a measured engineering article: MCP vs A2A vs Agent Skills. | E17: Uses your own code/results; diagrams; tradeoff table; reproducible examples. | F17: Published article / whitepaper | G17: 20 | H17: 4 | I17: Not Started
A18: 17 | B18: RAG Retrieval Quality Benchmark | C18: Core | D18: Build and measure a production-style retrieval pipeline before adding agent complexity. | E18: Create a labeled corpus/query set; compare keyword, vector, hybrid and reranked retrieval. Add chunking and metadata-filter ablations. | F18: Repo + Recall@K/MRR/nDCG table + latency/cost + failure taxonomy | G18: VERY HIGH | H18: 10 | I18: Not Started
A19: 18 | B19: RAG vs GraphRAG / Spanner Graph | C19: Advanced | D19: Determine when relationship-aware retrieval materially outperforms vector-only RAG. | E19: Build the same domain in vector RAG and Spanner Graph GraphRAG. Test multi-hop questions, entity relations and ambiguous queries. | F19: Benchmark + architecture ADR + graph schema + demo | G19: VERY HIGH | H19: 12 | I19: Not Started

Sheet Platform Library
A1: Provider | B1: Resource | C1: Format / Duration | D1: Use | E1: Open Link | F1: Canonical URL | G1: Back to Master Plan | H1: Validation | I1: Last Checked | J1: Audit Note
A2: Google Skills / GEAR | B2: Develop Agents with ADK | C2: Learning path | D2: Primary | E2: Open resource | F2: https://www.skills.google/paths/3545 | H2: Verified | I2: 46270 | J2: Link verified; sign-in may be required to launch/track course progress.
A3: Google Skills / GEAR | B3: Build Agents with ADK | C3: Course | D3: Primary | E3: Open resource | F3: https://www.skills.google/course_templates/1585 | H3: Verified | I3: 46270 | J3: Link verified; sign-in may be required to launch/track course progress.
A4: Google Skills / GEAR | B4: Build Your First Agent with ADK | C4: Hands-on course | D4: Primary | E4: Open resource | F4: https://partner.skills.google/course_templates/1563 | H4: Verified | I4: 46270 | J4: Link verified; sign-in may be required to launch/track course progress.
A5: Google Skills / GEAR | B5: Architect Multi-Agent Systems with ADK | C5: Learning path | D5: Primary | E5: Open resource | F5: https://www.skills.google/paths/3877 | H5: Verified | I5: 46270 | J5: Link verified; sign-in may be required to launch/track course progress.
A6: Google Skills / GEAR | B6: Build Collaborative Multi-Agent Systems with ADK & MCP | C6: Course | D6: Primary | E6: Open resource | F6: https://www.skills.google/course_templates/1833 | H6: Verified | I6: 46270 | J6: Direct Google Skills course URL verified via current search results; a path-scoped alias also exists.
A7: Google Skills / GEAR | B7: Deploy Production Ready Agents | C7: Learning path | D7: Primary | E7: Open resource | F7: https://www.skills.google/paths/3802 | H7: Verified | I7: 46270 | J7: Link verified; sign-in may be required to launch/track course progress.
A8: Google Skills / GEAR | B8: Use Agent Skills with Multi-Agent Systems | C8: Skill badge | D8: Primary | E8: Open resource | F8: https://www.skills.google/paths/4459/course_templates/1842 | H8: Verified | I8: 46270 | J8: Link verified; sign-in may be required to launch/track course progress.
A9: Google Codelabs | B9: Building AI Agents with ADK: Foundation | C9: Codelab | D9: Primary | E9: Open resource | F9: https://codelabs.developers.google.com/devsite/codelabs/build-agents-with-adk-foundation | H9: Verified | I9: 46270 | J9: Opened successfully during audit.
A10: Google Codelabs | B10: Building AI Agents with ADK: Empowering with Tools | C10: Codelab | D10: Primary | E10: Open resource | F10: https://codelabs.developers.google.com/devsite/codelabs/build-agents-with-adk-empowering-with-tools | H10: Verified | I10: 46270 | J10: Opened successfully during audit.
A11: Google Codelabs | B11: Getting Started with MCP, ADK and A2A | C11: Codelab | D11: Primary | E11: Open resource | F11: https://codelabs.developers.google.com/codelabs/currency-agent | H11: Verified | I11: 46270 | J11: Opened successfully during audit.
A12: Google Codelabs | B12: Multi-Agent Systems with Agent2Agent | C12: Codelab | D12: Primary | E12: Open resource | F12: https://codelabs.developers.google.com/next26/adk-agent2agent | H12: Verified | I12: 46270 | J12: Opened successfully during audit.
A13: Google Codelabs | B13: Multi-Agent Creative Studio: ADK + A2A + MCP | C13: Codelab | D13: Primary | E13: Open resource | F13: https://codelabs.developers.google.com/ai-creative-studio-adk-a2a?hl=en | H13: Verified | I13: 46270 | J13: Opened successfully during audit.
... A63: Harvard / edX | B63: CS50's Introduction to Artificial Intelligence with Python | C63: Course / 7 weeks | D63: Foundations secondary | E63: Open resource | F63: https://cs50.harvard.edu/ai/ | H63: Verified | I63: 46270 | J63: Opened successfully during audit.

Sheet 20-Week Plan
A1: Week | B1: Theme | C1: Primary Inputs | D1: Hands-On Deliverable | E1: Target Hours | F1: Start Date | G1: End Date
A2: 1 | B2: ADK orientation + first agent | C2: GEAR Build Agents; First Agent; Foundation codelab; Google ADK intro video | D2: First ADK Agent | E2: 6 | F2: 46296 | G2: 46302
A3: 2 | B3: ADK foundations | C3: Maurizio 1–7 | D3: Rebuild core agent from memory; architecture note | E3: 6 | F3: 46303 | G3: 46309
A4: 3 | B4: Tool engineering | C4: Maurizio 8–14; Google tools codelab; Anthropic tool article | D4: Tool Contract Lab | E4: 8 | F4: 46310 | G4: 46316
A5: 4 | B5: MCP basics | C5: LinkedIn MCP; Maurizio 27–28; Currency codelab start | D5: MCP Server | E5: 8 | F5: 46317 | G5: 46323
A6: 5 | B6: MCP efficiency + context | C6: Currency codelab finish; Anthropic code execution; Anthropic context article | D6: MCP benchmark | E6: 7 | F6: 46324 | G6: 46330
A7: 6 | B7: Multi-agent + A2A | C7: Maurizio 15–21.5; GEAR multi-agent; A2A codelab | D7: A2A Interop Lab | E7: 9 | F7: 46331 | G7: 46337
A8: 7 | B8: Distributed multi-agent | C8: Creative Studio codelab; Anthropic multi-agent article/video | D8: Multi-Agent Pattern Pack | E8: 9 | F8: 46338 | G8: 46344
A9: 8 | B9: Memory + artifacts | C9: Maurizio 22–23 | D9: Memory & Context Lab | E9: 6 | F9: 46345 | G9: 46351
A10: 9 | B10: Evaluation | C10: Maurizio 24; LinkedIn evals; Anthropic evals | D10: 100-Task Eval Harness v1 | E10: 9 | F10: 46352 | G10: 46358
A11: 10 | B11: Observability + recovery | C11: Maurizio 25–26; LinkedIn failure recovery; Kaggle 2025 Agents Intensive (quality/production units) | D11: Agent Observability | E11: 8 | F11: 46359 | G11: 46365
A12: 11 | B12: Security + governance | C12: LinkedIn governance; Google governance codelab; Anthropic containment | D12: Agent Red Team | E12: 9 | F12: 46366 | G12: 46372
A13: 12 | B13: Production deployment | C13: GEAR Deploy Production Ready; Maurizio 31–32 | D13: Cloud Run deployment | E13: 8 | F13: 46373 | G13: 46379
... A21: 20 | B21: Flagship capstone + writing | C21: Self-directed | D21: Deploy flagship system + publish architecture article | E21: 16 | F21: 46429 | G21: 46435

Sheet CS + Interview Track
A1: Area | B1: Resource | C1: Provider | D1: Priority | E1: Recommended Scope | F1: Why It Matters | G1: Proof / Practice | H1: Cadence | I1: URL | J1: Status | L1: Back to Master Plan
A2: Coding interviews | B2: LeetCode 75 | C2: LeetCode | D2: VERY HIGH | E2: Complete if rusty; otherwise use as diagnostic and focus on weak patterns. | F2: Google-style engineering interviews still require fast, correct algorithmic reasoning. | G2: Solve without hints; after each problem record pattern, complexity, edge cases, and one alternate solution. | H2: 3–5 problems/week in parallel | I2: Open resource | J2: Not Started
A3: Coding interviews | B3: Top Interview 150 | C3: LeetCode | D3: HIGH | E3: Use after LeetCode 75 or selectively for weak topics; do not blindly grind all 150 if already strong. | F3: Broader interview coverage and sustained timed practice. | G3: Weekly 45-minute mock block: 2 problems, explain before coding, test manually, then optimize. | H3: Selective / 2–4 problems/week | I3: Open resource | J3: Not Started
A4: System design | B4: Grokking Modern System Design Interview | C4: Educative | D4: VERY HIGH | E4: Prioritize distributed-system fundamentals + 8–10 case studies + mock interviews. | F4: Senior Google/Anthropic roles require architecture tradeoffs, reliability, consistency, capacity, queues, caches and failure handling. | G4: Do one 45-minute design from a blank page weekly; record requirements, estimates, API/data model, failure modes and tradeoffs. | H4: 2–3 h/week | I4: Open resource | J4: Not Started
A5: ML/AI system design | B5: Grokking the Machine Learning System Design Interview | C5: Educative | D5: VERY HIGH | E5: Complete the framework plus LLM/semantic-search/evaluation-related cases; selectively skim familiar ML basics. | F5: Bridges model quality, data, serving, experimentation and production architecture—the exact interface AI architects need. | G5: Design an LLM/agent platform under explicit latency, cost, eval, safety and rollout constraints. | H5: 1 design every 1–2 weeks | I5: Open resource | J5: Not Started
A6: Agent architecture | B6: Agentic System Design | C6: Educative | D6: HIGH | E6: Use as interview-oriented reinforcement, not as the primary agent course. | F6: Useful for practicing how to explain agent components, orchestration, guardrails and human oversight under interview constraints. | G6: Turn 5 scenarios into architecture decision records: agent vs workflow, single vs multi-agent, tool boundary, memory, eval and fallback. | H6: Selective / ~6 h total | I6: Open resource | J6: Not Started
A7: AI interview drills | B7: AI System Design Interview Questions | C7: Educative | D7: HIGH | E7: Use after system/ML design foundations; emphasize LLM serving, semantic search, safe fallbacks and observability. | F7: Converts broad architecture knowledge into interview-speed reasoning. | G7: Run timed mocks; after each, write what you missed and a better second-pass design. | H7: 1 mock/week late in plan | I7: Open resource | J7: Not Started
A8: Algorithms foundations | B8: MIT 6.006 — Introduction to Algorithms | C8: MIT OpenCourseWare | D8: HIGH | E8: Selective refresh: hashing, graphs, shortest paths, dynamic programming, complexity; do problem sets for weak areas. | F8: Deepens the reasoning behind interview patterns rather than memorizing LeetCode templates. | G8: Complete 2–3 MIT problem sets from your weakest topics without solutions, then compare. | H8: Parallel refresh | I8: Open resource | J8: Not Started
A9: Distributed systems | B9: MIT 6.824 — Distributed Computer Systems Engineering | C9: MIT OpenCourseWare | D9: VERY HIGH | E9: Selective deep study: fault tolerance, replication, consistency, distributed storage, naming and failure recovery. | F9: Agent platforms are distributed systems with stochastic components; these concepts remain foundational even though this OCW edition is older. | G9: Write design notes applying replication/consistency/failure concepts to an agent runtime, tool service and memory service. | H9: 1 topic/week | I9: Open resource | J9: Not Started
A10: Performance systems | B10: MIT 6.172 — Performance Engineering of Software Systems | C10: MIT OpenCourseWare | D10: HIGH | E10: Selective: profiling, caches, parallelism, synchronization, measurement; prioritize if targeting AI systems/infra roles. | F10: Frontier AI engineering increasingly rewards engineers who can reason about latency, throughput, parallelism and compute efficiency. | G10: Profile one agent service end-to-end and make a measured performance improvement with before/after evidence. | H10: Optional depth | I10: Open resource | J10: Not Started
A11: Classical AI | B11: MIT 6.034 — Artificial Intelligence | C11: MIT OpenCourseWare | D11: MEDIUM | E11: Select search, planning, constraints and probabilistic reasoning; skip material duplicated by stronger modern sources. | F11: Gives historical/algorithmic grounding for planning and search techniques that reappear in modern agents. | G11: Implement A*/minimax or a constraint solver and explicitly compare its deterministic search with LLM planning. | H11: Selective | I11: Open resource | J11: Not Started
A12: AI foundations | B12: CS50's Introduction to Artificial Intelligence with Python | C12: Harvard / edX | D12: HIGH | E12: Selective completion recommended for an experienced engineer: search, uncertainty, optimization, learning and language projects. | F12: Hands-on classical AI and ML fundamentals with real Python projects; good gap detector before deeper research material. | G12: Complete at least 3 projects from topics where your intuition is weakest; explain algorithmic choices and failure cases. | H12: Selective / project-driven | I12: Open resource | J12: Not Started

Sheet Stanford Research Track
A1: Order | B1: Resource / Paper | C1: Source | D1: Priority | E1: Why It Matters | F1: Hands-on Activity | G1: Evidence | H1: URL | I1: Status | K1: Back to Master Plan
A2: 1 | B2: CS329A — Self-Improving AI Agents | C2: Stanford | D2: VERY HIGH | E2: The strongest research-oriented course in this plan: test-time scaling, robust verification, tool/code feedback, multi-step planning, RL scaling, self-improvement, memory, coding agents and long-horizon evals. | F2: Follow lectures + core readings; choose one topic for a controlled replication/ablation. | G2: Course notes + replication report | H2: Open | I2: Not Started
A3: 2 | B3: CS329A Past Projects | C3: Stanford | D3: VERY HIGH | E3: Provides concrete examples of the research bar: AppBench, PRIME, meta-agents, ARCHON extensions, reasoning/RL and multi-agent verification. | F3: Review 5 projects; score each on novelty, experimental design, baselines, eval rigor and presentation. Use the best as a capstone-quality benchmark. | G3: Project-review rubric + capstone standard | H3: Open | I3: Not Started
A4: 3 | B4: Scaling Intelligence Lab — Research Themes | C4: Stanford | D4: VERY HIGH | E4: The lab explicitly focuses on scalable/self-improving AI, agentic optimization, automated verifiers/benchmarks, and AI systems. | F4: Use as an ongoing research radar; maintain a one-page map of themes and how your projects connect. | G4: Research map | H4: Open | I4: Not Started
A5: 4 | B5: Scaling Intelligence Lab — Publications | C5: Stanford | D5: VERY HIGH | E5: A concentrated feed of recent work directly relevant to frontier agent engineering. | F5: Read one paper/week during the advanced phase; reproduce or ablate at least one. | G5: Paper notes + one replication | H5: Open | I5: Not Started
A6: 5 | B6: LLM-as-a-Verifier: A General-Purpose Verification Framework | C6: Scaling Intelligence, 2026 | D6: VERY HIGH | E6: Verification is a core bottleneck for self-improving and long-horizon agents. | F6: Build a small verifier benchmark: correctness, false accept/reject, calibration and cost across two models. | G6: Verifier benchmark report | H6: Open paper | I6: Not Started
A7: 6 | B7: Decentralized Multi-Agent Systems with Shared Context | C7: Scaling Intelligence, 2026 | D7: VERY HIGH | E7: Directly relevant to multi-agent coordination and shared-context design beyond hierarchical supervisors. | F7: Compare centralized coordinator vs decentralized/shared-context architecture on the same task set. | G7: Architecture + benchmark | H7: Open paper | I7: Not Started
A8: 7 | B8: TRACE: Capability-Targeted Agentic Training | C8: Scaling Intelligence, 2026 | D8: HIGH | E8: Pushes beyond prompting/frameworks into training agents for targeted capabilities. | F8: Write an experiment design for one capability (tool use, recovery, planning); if compute permits, run a small-scale version. | G8: Experiment proposal/results | H8: Open paper | I8: Not Started
A9: 8 | B9: Weaver: Shrinking the Generation–Verification Gap with Weak Verifiers | C9: Scaling Intelligence, 2025 | D9: VERY HIGH | E9: Shows why verifier quality can limit self-improvement and how weak-verifier regimes behave. | F9: Reproduce a weak-vs-strong verifier comparison on a compact dataset. | G9: Ablation report | H9: Open paper | I9: Not Started
A10: 9 | B10: SPRINT: Interleaved Planning and Parallelized Execution | C10: Scaling Intelligence, 2025 | D10: VERY HIGH | E10: Closely aligned with scalable agent planning/execution and latency-aware orchestration. | F10: Implement sequential plan-execute vs interleaved/parallel execution; compare success, latency and token cost. | G10: Planning benchmark | H10: Open paper | I10: Not Started
A11: 10 | B11: CodeMonkeys: Scaling Test-Time Compute for Software Engineering | C11: Scaling Intelligence, 2025 | D11: VERY HIGH | E11: Connects coding agents, inference-time compute and software-engineering benchmarks. | F11: Run a small coding benchmark varying sampling/test-time budget; plot pass rate vs cost. | G11: Cost-quality curve + analysis | H11: Open paper | I11: Not Started
A12: 11 | B12: Archon: Architecture Search for Inference-Time Techniques | C12: Scaling Intelligence, 2024 | D12: VERY HIGH | E12: A useful bridge from manually designed agent workflows to automated inference architecture search. | F12: Implement 3 inference architectures (single, critic/ranker, planner+critic) and compare quality/cost. | G12: Architecture-search mini study | H12: Open paper | I12: Not Started
A13: 12 | B13: Aakanksha Chowdhery — Research Site | C13: Aakanksha Chowdhery | D13: HIGH | E13: Useful ongoing feed for self-improving agents, RL, reasoning and systems research; also co-instructor context for CS329A. | F13: Check quarterly, not weekly; pull only papers/talks that create a concrete experiment or design question. | G13: Research watch notes | H13: Open | I13: Not Started

Sheet Data + RAG Track
A1: Order | B1: Topic | C1: Resource | D1: Provider | E1: Priority | F1: When | G1: Why It Matters | H1: Hands-on Proof | I1: Evidence | J1: URL | K1: Status | M1: Back to Master Plan
A2: 1 | B2: Retrieval fundamentals | C2: Vector Search and Embeddings | D2: Google Skills / GEAR | E2: VERY HIGH | F2: Weeks 3–5 | G2: Learn embeddings, semantic search, hybrid retrieval and grounded RAG before adding agent orchestration. | H2: Build a small corpus; compare keyword, vector and hybrid retrieval on a labeled query set. | I2: Retrieval benchmark with Recall@K / MRR + failure notes | J2: Open resource | K2: Not Started
A3: 2 | B3: Agentic RAG | C3: Building Agents with Retrieval-Augmented Generation | D3: Google Codelabs | E3: VERY HIGH | F3: Weeks 4–6 | G3: Connect retrieval and structured tools to an ADK agent so the model decides when and how to retrieve. | H3: Complete the financial-analysis lab, then replace one data source with your own corpus/API. | I3: Agentic-RAG repo + eval set | J3: Open resource | K3: Not Started
A4: 3 | B4: Managed RAG | C4: Vertex AI RAG Engine quickstart | D4: Google Cloud | E4: HIGH | F4: Weeks 5–7 | G4: Understand production corpus ingestion, managed retrieval, metadata and retrieval APIs. | H4: Create a RAG corpus, ingest documents, retrieve contexts, and instrument latency/cost. | I4: RAG Engine notebook + architecture note | J4: Open resource | K4: Not Started
A5: 4 | B5: Retrieval quality | C5: Reranking for Vertex AI RAG Engine | D5: Google Cloud | E5: VERY HIGH | F5: Weeks 5–7 | G5: Retrieval quality often dominates answer quality; reranking is a core production technique. | H5: Compare baseline top-K retrieval vs reranked retrieval on at least 30 labeled queries. | I5: Before/after retrieval metrics + cost/latency | J5: Open resource | K5: Not Started
A6: 5 | B6: RAG evaluation | C6: Build a RAG evaluation harness | D6: Self-directed | E6: VERY HIGH | F6: Weeks 6–9 | G6: A RAG system needs separate retrieval and generation metrics; end-answer quality alone hides failure causes. | H6: Measure Recall@K/MRR/nDCG, context precision, groundedness, answer relevance and citation correctness. | I6: Reusable rag-evals package | J6: Open resource | K6: Not Started
A7: 6 | B7: Graph fundamentals | C7: Getting started with Spanner Graph | D7: Google Codelabs | E7: HIGH | F7: Weeks 7–9 | G7: Learn property graphs, nodes/edges, ISO GQL pattern matching, traversal, and relational/graph interoperability. | H7: Complete the codelab, then model one domain from your capstone as nodes/edges and write 8 GQL queries. | I7: Graph schema + GQL query pack | J7: Open resource | K7: Not Started
A8: 7 | B8: GraphRAG architecture | C8: GraphRAG infrastructure using Agent Platform and Spanner Graph | D8: Google Cloud Architecture Center | E8: VERY HIGH | F8: Weeks 8–11 | G8: GraphRAG combines vector retrieval with graph traversal for relationship-aware, multi-hop context. | H8: Design ingestion + serving architecture; explicitly decide what belongs in vectors, relational columns and graph edges. | I8: Architecture diagram + ADR | J8: Open resource | K8: Not Started
A9: 8 | B9: GraphRAG implementation | C9: Build GraphRAG with Spanner Graph and LangChain | D9: Google Cloud | E9: HIGH | F9: Weeks 9–12 | G9: See a practical knowledge-graph construction and retrieval flow using vector and graph queries together. | H9: Implement a miniature GraphRAG corpus and compare answers against vector-only RAG. | I9: RAG vs GraphRAG benchmark | J9: Open resource | K9: Not Started
A10: 9 | B10: Graph algorithms | C10: Spanner Graph algorithms overview | D10: Google Cloud | E10: MEDIUM | F10: Weeks 12–16 | G10: Centrality, clustering, similarity and path finding matter for entity resolution, recommendation, fraud and graph-assisted retrieval. | H10: Run at least two graph algorithms and show when algorithmic graph signals improve retrieval or ranking. | I10: Graph-algorithm experiment | J10: Open resource | K10: Not Started
A11: 10 | B11: Distributed data systems | C11: Spanner: Google's Globally-Distributed Database | D11: Google Research | E11: VERY HIGH | F11: Weeks 10–16 | G11: Build first-principles intuition for sharding, synchronous replication, external consistency, MVCC and TrueTime. | H11: Write a 2-page systems note mapping Spanner guarantees to agent state, memory, tool transactions and multi-region services. | I11: Systems-design note | J11: Open resource | K11: Not Started
A12: 11 | B12: Consistency concepts | C12: TrueTime and external consistency | D12: Google Cloud | E12: HIGH | F12: Weeks 10–16 | G12: Strong consistency and transaction ordering become important when autonomous agents mutate shared state. | H12: Design a shared-agent-state scenario; identify anomalies under weaker consistency and how external consistency changes the design. | I12: Consistency failure analysis | J12: Open resource | K12: Not Started

Sheet Competency Matrix
A1: Domain | B1: Competency | C1: Target Level | D1: Current Level | E1: Readiness % | F1: Google Relevance | G1: Anthropic Relevance | H1: Evidence Required | I1: Primary Track | J1: Go to Track | K1: Key Master Items | L1: Target Date | M1: Assessment Standard | N1: Status | O1: Gap to Target | P1: Notes | Q1: Level Guide | S1: Back to Master Plan
A2: Software Engineering | B2: Python / production coding | C2: 4 | D2: 0 | E2: =IFERROR(MIN(1,D2/C2),0) -> 0 | F2: VERY HIGH | G2: VERY HIGH | H2: Clean tested repo; async/concurrency; APIs; typing; error handling; CI; code review quality. | I2: Master Plan | J2: =HYPERLINK("#'Master Plan'!A1","Open track") -> Open track | K2: Agent runtime; capstone; coding-agent workflow | L2: 46421 | M2: Can implement unfamiliar systems under time pressure and defend design/test choices. | N2: Not Started | O2: =MAX(0,C2-D2) -> 4 | Q2: 0=None | 1=Awareness | 2=Practitioner | 3=Advanced | 4=Independent mastery
